Workbook

Sheet Choix pédagogiques
A1: Vos choix pédagogiques
B3: Variante choisie : 1 = "deux années" ; 2 = "deux groupes" ; 3 = "deux enseignements" | C3: ?
B4: Note minimale possible | C4: ?
B5: Note maximale possible | C5: ?
B7: =IF(C3="?","",IF(AND(C3<>1,C3<>2),"","Variante 1 ou 2"))
B8: =IF(C3="?","",IF(AND(C3<>1,C3<>2),"","Nombre potentiel d'apprenants du groupe bénéficiant de la pratique pédagogique habituelle")) | C8: =IF(C3="?"," ",IF(C3<>3,"?"," "))
B9: =IF(C3="?","",IF(AND(C3<>1,C3<>2),"","Nombre potentiel d'apprenants du groupe bénéficiant de la nouvelle pratique pédagogique")) | C9: =IF(C3="?"," ",IF(C3<>3,"?"," "))
B10: =IF(C3="?","",IF(AND(C3<>1,C3<>2),"","Nombre d'apprenants du groupe bénéficiant de la pratique pédagogique habituelle effectivement présents aux trois tests")) | C10: =IF(AND(COUNT('Données brutes'!W13:W1012)<>0,OR(C3=1,C3=2)),COUNT('Données brutes'!W13:W1012),"")
B11: =IF(C3="?","",IF(AND(C3<>1,C3<>2),"","Nombre d'apprenants du groupe bénéficiant de la nouvelle pratique pédagogique effectivement présents aux trois tests")) | C11: =IF(AND(COUNT('Données brutes'!AB13:AB1012)<>0,OR(C3=1,C3=2)),COUNT('Données brutes'!AB13:AB1012),"")
B12: =IF(C3="?","",IF(AND(C3<>1,C3<>2),"","Taux de participation du groupe bénéficiant de la pratique pédagogique habituelle")) | C12: =IF(AND(C8<>"?",C10<>""),C10/C8,"")
B13: =IF(C3="?","",IF(AND(C3<>1,C3<>2),"","Taux de participation du groupe bénéficiant de la nouvelle pratique pédagogique")) | C13: =IF(AND(C9<>"?",C11<>""),C11/C9,"")
B15: =IF(C3="?","",IF(C3<>3,"","Variante 3"))
B16: =IF(C3="?","",IF(C3<>3,"","Nombre potentiel d'apprenants participant à l'évaluation")) | C16: =IF(C3=" ","?",IF(C3<>3," ","?"))
B17: =IF(C3="?","",IF(C3<>3,"","Nombre d'apprenants effectivement présents aux six tests")) | C17: =IF(AND(COUNT('Données brutes'!Y13:Y1012)<>0,C3=3),COUNT('Données brutes'!Y13:Y1012),"")
B18: =IF(C3="?","",IF(C3<>3,"","Taux de participation")) | C18: =IF(AND(C16<>"?",C17<>""),C17/C16,"")

Sheet Données brutes
A1: Données brutes | F1: Données brutes | K1: Données brutes | P1: Données brutes | V1: Données brutes pour les participants présents à tous les tests | AA1: Données brutes pour les participants présents à tous les tests | AF1: Données brutes pour les participants présents à tous les tests | AK1: Données brutes pour les participants présents à tous les tests | AQ1: Probabilités de réussite pour les participants présents à tous les tests | AV1: Probabilités de réussite pour les participants présents à tous les tests | BA1: Probabilités de réussite pour les participants présents à tous les tests | BF1: Probabilités de réussite pour les participants présents à tous les tests
A2: Scores | F2: Scores | K2: Évolution des scores | P2: Évolution des scores | V2: Scores | AA2: Scores | AF2: Évolution des scores | AK2: Évolution des scores | AQ2: Probabilités de réussite | AV2: Probabilités de réussite | BA2: Évolution des probabilités de réussite | BF2: Évolution des probabilités de réussite | BM2: Le participant est-il présent à tous les tests ? 1 oui, 0 non | BR2: Numéro d'anonymisation
A3: Pratique pédagogie habituelle | F3: Nouvelle pratique pédagogique | K3: Pratique pédagogique habituelle | P3: Nouvelle pratique pédagogique | V3: Pratique pédagogie habituelle | AA3: Nouvelle pratique pédagogique | AF3: Pratique pédagogique habituelle | AK3: Nouvelle pratique pédagogique | AQ3: Pratique pédagogie habituelle | AV3: Nouvelle pratique pédagogique | BA3: Pratique pédagogique habituelle | BF3: Nouvelle pratique pédagogique | BM3: Variante 1 ou 2 | BN3: Variante 1 ou 2 | BO3: Variante 3
B4: Pré-test | C4: Post-test immédiat | D4: Post-test différé | E4: Commentaire | G4: Pré-test | H4: Post-test immédiat | I4: Post-test différé | J4: Commentaire | L4: Évolution à court terme (post-test immédiat - pré-test) | M4: Évolution à moyen terme (post-test différé - pré-test) | N4: Évolution a posteriori (post-test différé - post-test immédiat) | O4: Commentaire | Q4: Évolution à court terme (post-test immédiat - pré-test) | R4: Évolution à moyen terme (post-test différé - pré-test) | S4: Évolution a posteriori (post-test différé - post-test immédiat) | T4: Commentaire | W4: Pré-test | X4: Post-test immédiat | Y4: Post-test différé | Z4: Commentaire | AB4: Pré-test | AC4: Post-test immédiat | AD4: Post-test différé | AE4: Commentaire | AG4: Évolution à court terme (post-test immédiat - pré-test) | AH4: Évolution à moyen terme (post-test différé - pré-test) | AI4: Évolution a posteriori (post-test différé - post-test immédiat) | AJ4: Commentaire | AL4: Évolution à court terme (post-test immédiat - pré-test) | AM4: Évolution à moyen terme (post-test différé - pré-test) | AN4: Évolution a posteriori (post-test différé - post-test immédiat) | AO4: Commentaire | AR4: Pré-test | AS4: Post-test immédiat | AT4: Post-test différé | AU4: Commentaire | AW4: Pré-test | AX4: Post-test immédiat | AY4: Post-test différé | AZ4: Commentaire | BB4: Évolution à court terme (post-test immédiat - pré-test) | BC4: Évolution à moyen terme (post-test différé - pré-test) | BD4: Évolution a posteriori (post-test différé - post-test immédiat) | BE4: Commentaire | BG4: Évolution à court terme (post-test immédiat - pré-test) | BH4: Évolution à moyen terme (post-test différé - pré-test) | BI4: Évolution a posteriori (post-test différé - post-test immédiat) | BJ4: Commentaire | BM4: Pratique pédagogique habituelle (trois tests) | BN4: Nouvelle pratique pédagogique (trois tests) | BO4: Pratiques pédagogiques habituelle et nouvelle (six tests) | BR4: Variantes 1 ou 2 Pratique pédagogique habituelle & Variantes 3 Pratiques pédagogiques habituelle et nouvelle | BS4: Variante 1 ou 2 Nouvelle pratique pédagogique
A5: Moyenne | B5: =IF(COUNT(B13:B1012)=0,"",AVERAGE(B13:B1012)) | C5: =IF(COUNT(C13:C1012)=0,"",AVERAGE(C13:C1012)) | D5: =IF(COUNT(D13:D1012)=0,"",AVERAGE(D13:D1012)) | F5: Moyenne | G5: =IF(COUNT(G13:G1012)=0,"",AVERAGE(G13:G1012)) | H5: =IF(COUNT(H13:H1012)=0,"",AVERAGE(H13:H1012)) | I5: =IF(COUNT(I13:I1012)=0,"",AVERAGE(I13:I1012)) | K5: Moyenne | L5: =IF(COUNT(L13:L1012)=0,"",AVERAGE(L13:L1012)) | M5: =IF(COUNT(M13:M1012)=0,"",AVERAGE(M13:M1012)) | N5: =IF(COUNT(N13:N1012)=0,"",AVERAGE(N13:N1012)) | P5: Moyenne | Q5: =IF(COUNT(Q13:Q1012)=0,"",AVERAGE(Q13:Q1012)) | R5: =IF(COUNT(R13:R1012)=0,"",AVERAGE(R13:R1012)) | S5: =IF(COUNT(S13:S1012)=0,"",AVERAGE(S13:S1012)) | V5: Moyenne | W5: =IF(COUNT(W13:W1012)=0,"",AVERAGE(W13:W1012)) | X5: =IF(COUNT(X13:X1012)=0,"",AVERAGE(X13:X1012)) | Y5: =IF(COUNT(Y13:Y1012)=0,"",AVERAGE(Y13:Y1012)) | AA5: Moyenne | AB5: =IF(COUNT(AB13:AB1012)=0,"",AVERAGE(AB13:AB1012)) | AC5: =IF(COUNT(AC13:AC1012)=0,"",AVERAGE(AC13:AC1012)) | AD5: =IF(COUNT(AD13:AD1012)=0,"",AVERAGE(AD13:AD1012)) | AF5: Moyenne | AG5: =IF(COUNT(AG13:AG1012)=0,"",AVERAGE(AG13:AG1012)) | AH5: =IF(COUNT(AH13:AH1012)=0,"",AVERAGE(AH13:AH1012)) | AI5: =IF(COUNT(AI13:AI1012)=0,"",AVERAGE(AI13:AI1012)) | AK5: Moyenne | AL5: =IF(COUNT(AL13:AL1012)=0,"",AVERAGE(AL13:AL1012)) | AM5: =IF(COUNT(AM13:AM1012)=0,"",AVERAGE(AM13:AM1012)) | AN5: =IF(COUNT(AN13:AN1012)=0,"",AVERAGE(AN13:AN1012)) | AQ5: Moyenne | AR5: =IF(COUNT(AR13:AR1012)=0,"",AVERAGE(AR13:AR1012)) | AS5: =IF(COUNT(AS13:AS1012)=0,"",AVERAGE(AS13:AS1012)) | AT5: =IF(COUNT(AT13:AT1012)=0,"",AVERAGE(AT13:AT1012)) | AV5: Moyenne | AW5: =IF(COUNT(AW13:AW1012)=0,"",AVERAGE(AW13:AW1012)) | AX5: =IF(COUNT(AX13:AX1012)=0,"",AVERAGE(AX13:AX1012)) | AY5: =IF(COUNT(AY13:AY1012)=0,"",AVERAGE(AY13:AY1012)) | BA5: Moyenne | BB5: =IF(COUNT(BB13:BB1012)=0,"",AVERAGE(BB13:BB1012)) | BC5: =IF(COUNT(BC13:BC1012)=0,"",AVERAGE(BC13:BC1012)) | BD5: =IF(COUNT(BD13:BD1012)=0,"",AVERAGE(BD13:BD1012)) | BF5: Moyenne | BG5: =IF(COUNT(BG13:BG1012)=0,"",AVERAGE(BG13:BG1012)) | BH5: =IF(COUNT(BH13:BH1012)=0,"",AVERAGE(BH13:BH1012)) | BI5: =IF(COUNT(BI13:BI1012)=0,"",AVERAGE(BI13:BI1012)) | BL5: Nombre de présents | BM5: =IF(AND('Choix pédagogiques'!C3<>1,'Choix pédagogiques'!C3<>2),"",SUM(BM13:BM1012)) | BN5: =IF(AND('Choix pédagogiques'!C3<>1,'Choix pédagogiques'!C3<>2),"",SUM(BN13:BN1012)) | BO5: =IF(OR(COUNT(BO13:BO1012)=0,'Choix pédagogiques'!C3<>3),"",SUM(BO13:BO1012))
A6: Écart-type | B6: =IF(COUNT(B13:B1012)<2,"",_xlfn.STDEV.S(B13:B1012)) | C6: =IF(COUNT(C13:C1012)<2,"",_xlfn.STDEV.S(C13:C1012)) | D6: =IF(COUNT(D13:D1012)<2,"",_xlfn.STDEV.S(D13:D1012)) | F6: Écart-type | G6: =IF(COUNT(G13:G1012)<2,"",_xlfn.STDEV.S(G13:G1012)) | H6: =IF(COUNT(H13:H1012)<2,"",_xlfn.STDEV.S(H13:H1012)) | I6: =IF(COUNT(I13:I1012)<2,"",_xlfn.STDEV.S(I13:I1012)) | K6: Écart-type | L6: =IF(COUNT(L13:L1012)<2,"",_xlfn.STDEV.S(L13:L1012)) | M6: =IF(COUNT(M13:M1012)<2,"",_xlfn.STDEV.S(M13:M1012)) | N6: =IF(COUNT(N13:N1012)<2,"",_xlfn.STDEV.S(N13:N1012)) | P6: Écart-type | Q6: =IF(COUNT(Q13:Q1012)<2,"",_xlfn.STDEV.S(Q13:Q1012)) | R6: =IF(COUNT(R13:R1012)<2,"",_xlfn.STDEV.S(R13:R1012)) | S6: =IF(COUNT(S13:S1012)<2,"",_xlfn.STDEV.S(S13:S1012)) | V6: Écart-type | W6: =IF(COUNT(W13:W1012)<2,"",_xlfn.STDEV.S(W13:W1012)) | X6: =IF(COUNT(X13:X1012)<2,"",_xlfn.STDEV.S(X13:X1012)) | Y6: =IF(COUNT(Y13:Y1012)<2,"",_xlfn.STDEV.S(Y13:Y1012)) | AA6: Écart-type | AB6: =IF(COUNT(AB13:AB1012)<2,"",_xlfn.STDEV.S(AB13:AB1012)) | AC6: =IF(COUNT(AC13:AC1012)<2,"",_xlfn.STDEV.S(AC13:AC1012)) | AD6: =IF(COUNT(AD13:AD1012)<2,"",_xlfn.STDEV.S(AD13:AD1012)) | AF6: Écart-type | AG6: =IF(COUNT(AG13:AG1012)<2,"",_xlfn.STDEV.S(AG13:AG1012)) | AH6: =IF(COUNT(AH13:AH1012)<2,"",_xlfn.STDEV.S(AH13:AH1012)) | AI6: =IF(COUNT(AI13:AI1012)<2,"",_xlfn.STDEV.S(AI13:AI1012)) | AK6: Écart-type | AL6: =IF(COUNT(AL13:AL1012)<2,"",_xlfn.STDEV.S(AL13:AL1012)) | AM6: =IF(COUNT(AM13:AM1012)<2,"",_xlfn.STDEV.S(AM13:AM1012)) | AN6: =IF(COUNT(AN13:AN1012)<2,"",_xlfn.STDEV.S(AN13:AN1012)) | AQ6: Écart-type | AR6: =IF(COUNT(AR13:AR1012)<2,"",_xlfn.STDEV.S(AR13:AR1012)) | AS6: =IF(COUNT(AS13:AS1012)<2,"",_xlfn.STDEV.S(AS13:AS1012)) | AT6: =IF(COUNT(AT13:AT1012)<2,"",_xlfn.STDEV.S(AT13:AT1012)) | AV6: Écart-type | AW6: =IF(COUNT(AW13:AW1012)<2,"",_xlfn.STDEV.S(AW13:AW1012)) | AX6: =IF(COUNT(AX13:AX1012)<2,"",_xlfn.STDEV.S(AX13:AX1012)) | AY6: =IF(COUNT(AY13:AY1012)<2,"",_xlfn.STDEV.S(AY13:AY1012)) | BA6: Écart-type | BB6: =IF(COUNT(BB13:BB1012)<2,"",_xlfn.STDEV.S(BB13:BB1012)) | BC6: =IF(COUNT(BC13:BC1012)<2,"",_xlfn.STDEV.S(BC13:BC1012)) | BD6: =IF(COUNT(BD13:BD1012)<2,"",_xlfn.STDEV.S(BD13:BD1012)) | BF6: Écart-type | BG6: =IF(COUNT(BG13:BG1012)<2,"",_xlfn.STDEV.S(BG13:BG1012)) | BH6: =IF(COUNT(BH13:BH1012)<2,"",_xlfn.STDEV.S(BH13:BH1012)) | BI6: =IF(COUNT(BI13:BI1012)<2,"",_xlfn.STDEV.S(BI13:BI1012)) | BL6: Nombre total | BM6: =IF(AND('Choix pédagogiques'!C3<>1,'Choix pédagogiques'!C3<>2),"",'Choix pédagogiques'!C8) | BN6: =IF(AND('Choix pédagogiques'!C3<>1,'Choix pédagogiques'!C3<>2),"",'Choix pédagogiques'!C9) | BO6: =IF(OR(BO5="",'Choix pédagogiques'!C3<>3),"",'Choix pédagogiques'!C16)
A7: Intervalle de confiance | B7: =IF(OR('Choix pédagogiques'!$C$3=1,'Choix pédagogiques'!$C$3=2),IF(OR(COUNT(B13:B1012)<2,'Choix pédagogiques'!$C10=""),"",IF(B6=0,0,_xlfn.CONFIDENCE.NORM(0.05,B6,'Choix pédagogiques'!$C10))),IF('Choix pédagogiques'!$C$3=3,IF(OR(COUNT(B13:B1012)<2,'Choix pédagogiques'!$C17=""),"",IF(B6=0,0,_xlfn.CONFIDENCE.NORM(0.05,B6,'Choix pédagogiques'!$C17))),"")) | C7: =IF(OR('Choix pédagogiques'!$C$3=1,'Choix pédagogiques'!$C$3=2),IF(OR(COUNT(C13:C1012)<2,'Choix pédagogiques'!$C10=""),"",IF(C6=0,0,_xlfn.CONFIDENCE.NORM(0.05,C6,'Choix pédagogiques'!$C10))),IF('Choix pédagogiques'!$C$3=3,IF(OR(COUNT(C13:C1012)<2,'Choix pédagogiques'!$C17=""),"",IF(C6=0,0,_xlfn.CONFIDENCE.NORM(0.05,C6,'Choix pédagogiques'!$C17))),"")) | D7: =IF(OR('Choix pédagogiques'!$C$3=1,'Choix pédagogiques'!$C$3=2),IF(OR(COUNT(D13:D1012)<2,'Choix pédagogiques'!$C10=""),"",IF(D6=0,0,_xlfn.CONFIDENCE.NORM(0.05,D6,'Choix pédagogiques'!$C10))),IF('Choix pédagogiques'!$C$3=3,IF(OR(COUNT(D13:D1012)<2,'Choix pédagogiques'!$C17=""),"",IF(D6=0,0,_xlfn.CONFIDENCE.NORM(0.05,D6,'Choix pédagogiques'!$C17))),"")) | F7: Intervalle de confiance | G7: =IF(OR('Choix pédagogiques'!$C$3=1,'Choix pédagogiques'!$C$3=2),IF(OR(COUNT(G13:G1012)<2,'Choix pédagogiques'!$C11=""),"",IF(G6=0,0,_xlfn.CONFIDENCE.NORM(0.05,G6,'Choix pédagogiques'!$C11))),IF('Choix pédagogiques'!$C$3=3,IF(OR(COUNT(G13:G1012)<2,'Choix pédagogiques'!$C17=""),"",IF(G6=0,0,_xlfn.CONFIDENCE.NORM(0.05,G6,'Choix pédagogiques'!$C17))),"")) | H7: =IF(OR('Choix pédagogiques'!$C$3=1,'Choix pédagogiques'!$C$3=2),IF(OR(COUNT(H13:H1012)<2,'Choix pédagogiques'!$C11=""),"",IF(H6=0,0,_xlfn.CONFIDENCE.NORM(0.05,H6,'Choix pédagogiques'!$C11))),IF('Choix pédagogiques'!$C$3=3,IF(OR(COUNT(H13:H1012)<2,'Choix pédagogiques'!$C17=""),"",IF(H6=0,0,_xlfn.CONFIDENCE.NORM(0.05,H6,'Choix pédagogiques'!$C17))),"")) | I7: =IF(OR('Choix pédagogiques'!$C$3=1,'Choix pédagogiques'!$C$3=2),IF(OR(COUNT(I13:I1012)<2,'Choix pédagogiques'!$C11=""),"",IF(I6=0,0,_xlfn.CONFIDENCE.NORM(0.05,I6,'Choix pédagogiques'!$C11))),IF('Choix pédagogiques'!$C$3=3,IF(OR(COUNT(I13:I1012)<2,'Choix pédagogiques'!$C17=""),"",IF(I6=0,0,_xlfn.CONFIDENCE.NORM(0.05,I6,'Choix pédagogiques'!$C17))),"")) | K7: Intervalle de confiance | L7: =IF(OR('Choix pédagogiques'!$C$3=1,'Choix pédagogiques'!$C$3=2),IF(OR(COUNT(L13:L1012)<2,'Choix pédagogiques'!$C10=""),"",IF(L6=0,0,_xlfn.CONFIDENCE.NORM(0.05,L6,'Choix pédagogiques'!$C10))),IF('Choix pédagogiques'!$C$3=3,IF(OR(COUNT(L13:L1012)<2,'Choix pédagogiques'!$C17=""),"",IF(L6=0,0,_xlfn.CONFIDENCE.NORM(0.05,L6,'Choix pédagogiques'!$C17))),"")) | M7: =IF(OR('Choix pédagogiques'!$C$3=1,'Choix pédagogiques'!$C$3=2),IF(OR(COUNT(M13:M1012)<2,'Choix pédagogiques'!$C10=""),"",IF(M6=0,0,_xlfn.CONFIDENCE.NORM(0.05,M6,'Choix pédagogiques'!$C10))),IF('Choix pédagogiques'!$C$3=3,IF(OR(COUNT(M13:M1012)<2,'Choix pédagogiques'!$C17=""),"",IF(M6=0,0,_xlfn.CONFIDENCE.NORM(0.05,M6,'Choix pédagogiques'!$C17))),"")) | N7: =IF(OR('Choix pédagogiques'!$C$3=1,'Choix pédagogiques'!$C$3=2),IF(OR(COUNT(N13:N1012)<2,'Choix pédagogiques'!$C10=""),"",IF(N6=0,0,_xlfn.CONFIDENCE.NORM(0.05,N6,'Choix pédagogiques'!$C10))),IF('Choix pédagogiques'!$C$3=3,IF(OR(COUNT(N13:N1012)<2,'Choix pédagogiques'!$C17=""),"",IF(N6=0,0,_xlfn.CONFIDENCE.NORM(0.05,N6,'Choix pédagogiques'!$C17))),"")) | P7: Intervalle de confiance | Q7: =IF(OR('Choix pédagogiques'!$C$3=1,'Choix pédagogiques'!$C$3=2),IF(OR(COUNT(Q13:Q1012)<2,'Choix pédagogiques'!$C11=""),"",IF(Q6=0,0,_xlfn.CONFIDENCE.NORM(0.05,Q6,'Choix pédagogiques'!$C11))),IF('Choix pédagogiques'!$C$3=3,IF(OR(COUNT(Q13:Q1012)<2,'Choix pédagogiques'!$C17=""),"",IF(Q6=0,0,_xlfn.CONFIDENCE.NORM(0.05,Q6,'Choix pédagogiques'!$C17))),"")) | R7: =IF(OR('Choix pédagogiques'!$C$3=1,'Choix pédagogiques'!$C$3=2),IF(OR(COUNT(R13:R1012)<2,'Choix pédagogiques'!$C11=""),"",IF(R6=0,0,_xlfn.CONFIDENCE.NORM(0.05,R6,'Choix pédagogiques'!$C11))),IF('Choix pédagogiques'!$C$3=3,IF(OR(COUNT(R13:R1012)<2,'Choix pédagogiques'!$C17=""),"",IF(R6=0,0,_xlfn.CONFIDENCE.NORM(0.05,R6,'Choix pédagogiques'!$C17))),"")) | S7: =IF(OR('Choix pédagogiques'!$C$3=1,'Choix pédagogiques'!$C$3=2),IF(OR(COUNT(S13:S1012)<2,'Choix pédagogiques'!$C11=""),"",IF(S6=0,0,_xlfn.CONFIDENCE.NORM(0.05,S6,'Choix pédagogiques'!$C11))),IF('Choix pédagogiques'!$C$3=3,IF(OR(COUNT(S13:S1012)<2,'Choix pédagogiques'!$C17=""),"",IF(S6=0,0,_xlfn.CONFIDENCE.NORM(0.05,S6,'Choix pédagogiques'!$C17))),"")) | V7: Intervalle de confiance | W7: =IF(OR('Choix pédagogiques'!$C$3=1,'Choix pédagogiques'!$C$3=2),IF(OR(COUNT(W13:W1012)<2,'Choix pédagogiques'!$C10=""),"",IF(W6=0,0,_xlfn.CONFIDENCE.NORM(0.05,W6,'Choix pédagogiques'!$C10))),IF('Choix pédagogiques'!$C$3=3,IF(OR(COUNT(W13:W1012)<2,'Choix pédagogiques'!$C17=""),"",IF(W6=0,0,_xlfn.CONFIDENCE.NORM(0.05,W6,'Choix pédagogiques'!$C17))),"")) | X7: =IF(OR('Choix pédagogiques'!$C$3=1,'Choix pédagogiques'!$C$3=2),IF(OR(COUNT(X13:X1012)<2,'Choix pédagogiques'!$C10=""),"",IF(X6=0,0,_xlfn.CONFIDENCE.NORM(0.05,X6,'Choix pédagogiques'!$C10))),IF('Choix pédagogiques'!$C$3=3,IF(OR(COUNT(X13:X1012)<2,'Choix pédagogiques'!$C17=""),"",IF(X6=0,0,_xlfn.CONFIDENCE.NORM(0.05,X6,'Choix pédagogiques'!$C17))),"")) | Y7: =IF(OR('Choix pédagogiques'!$C$3=1,'Choix pédagogiques'!$C$3=2),IF(OR(COUNT(Y13:Y1012)<2,'Choix pédagogiques'!$C10=""),"",IF(Y6=0,0,_xlfn.CONFIDENCE.NORM(0.05,Y6,'Choix pédagogiques'!$C10))),IF('Choix pédagogiques'!$C$3=3,IF(OR(COUNT(Y13:Y1012)<2,'Choix pédagogiques'!$C17=""),"",IF(Y6=0,0,_xlfn.CONFIDENCE.NORM(0.05,Y6,'Choix pédagogiques'!$C17))),"")) | AA7: Intervalle de confiance | AB7: =IF(OR('Choix pédagogiques'!$C$3=1,'Choix pédagogiques'!$C$3=2),IF(OR(COUNT(AB13:AB1012)<2,'Choix pédagogiques'!$C11=""),"",IF(AB6=0,0,_xlfn.CONFIDENCE.NORM(0.05,AB6,'Choix pédagogiques'!$C11))),IF('Choix pédagogiques'!$C$3=3,IF(OR(COUNT(AB13:AB1012)<2,'Choix pédagogiques'!$C17=""),"",IF(AB6=0,0,_xlfn.CONFIDENCE.NORM(0.05,AB6,'Choix pédagogiques'!$C17))),"")) | AC7: =IF(OR('Choix pédagogiques'!$C$3=1,'Choix pédagogiques'!$C$3=2),IF(OR(COUNT(AC13:AC1012)<2,'Choix pédagogiques'!$C11=""),"",IF(AC6=0,0,_xlfn.CONFIDENCE.NORM(0.05,AC6,'Choix pédagogiques'!$C11))),IF('Choix pédagogiques'!$C$3=3,IF(OR(COUNT(AC13:AC1012)<2,'Choix pédagogiques'!$C17=""),"",IF(AC6=0,0,_xlfn.CONFIDENCE.NORM(0.05,AC6,'Choix pédagogiques'!$C17))),"")) | AD7: =IF(OR('Choix pédagogiques'!$C$3=1,'Choix pédagogiques'!$C$3=2),IF(OR(COUNT(AD13:AD1012)<2,'Choix pédagogiques'!$C11=""),"",IF(AD6=0,0,_xlfn.CONFIDENCE.NORM(0.05,AD6,'Choix pédagogiques'!$C11))),IF('Choix pédagogiques'!$C$3=3,IF(OR(COUNT(AD13:AD1012)<2,'Choix pédagogiques'!$C17=""),"",IF(AD6=0,0,_xlfn.CONFIDENCE.NORM(0.05,AD6,'Choix pédagogiques'!$C17))),"")) | AF7: Intervalle de confiance | AG7: =IF(OR('Choix pédagogiques'!$C$3=1,'Choix pédagogiques'!$C$3=2),IF(OR(COUNT(AG13:AG1012)<2,'Choix pédagogiques'!$C10=""),"",IF(AG6=0,0,_xlfn.CONFIDENCE.NORM(0.05,AG6,'Choix pédagogiques'!$C10))),IF('Choix pédagogiques'!$C$3=3,IF(OR(COUNT(AG13:AG1012)<2,'Choix pédagogiques'!$C17=""),"",IF(AG6=0,0,_xlfn.CONFIDENCE.NORM(0.05,AG6,'Choix pédagogiques'!$C17))),"")) | AH7: =IF(OR('Choix pédagogiques'!$C$3=1,'Choix pédagogiques'!$C$3=2),IF(OR(COUNT(AH13:AH1012)<2,'Choix pédagogiques'!$C10=""),"",IF(AH6=0,0,_xlfn.CONFIDENCE.NORM(0.05,AH6,'Choix pédagogiques'!$C10))),IF('Choix pédagogiques'!$C$3=3,IF(OR(COUNT(AH13:AH1012)<2,'Choix pédagogiques'!$C17=""),"",IF(AH6=0,0,_xlfn.CONFIDENCE.NORM(0.05,AH6,'Choix pédagogiques'!$C17))),"")) | AI7: =IF(OR('Choix pédagogiques'!$C$3=1,'Choix pédagogiques'!$C$3=2),IF(OR(COUNT(AI13:AI1012)<2,'Choix pédagogiques'!$C10=""),"",IF(AI6=0,0,_xlfn.CONFIDENCE.NORM(0.05,AI6,'Choix pédagogiques'!$C10))),IF('Choix pédagogiques'!$C$3=3,IF(OR(COUNT(AI13:AI1012)<2,'Choix pédagogiques'!$C17=""),"",IF(AI6=0,0,_xlfn.CONFIDENCE.NORM(0.05,AI6,'Choix pédagogiques'!$C17))),"")) | AK7: Intervalle de confiance | AL7: =IF(OR('Choix pédagogiques'!$C$3=1,'Choix pédagogiques'!$C$3=2),IF(OR(COUNT(AL13:AL1012)<2,'Choix pédagogiques'!$C11=""),"",IF(AL6=0,0,_xlfn.CONFIDENCE.NORM(0.05,AL6,'Choix pédagogiques'!$C11))),IF('Choix pédagogiques'!$C$3=3,IF(OR(COUNT(AL13:AL1012)<2,'Choix pédagogiques'!$C17=""),"",IF(AL6=0,0,_xlfn.CONFIDENCE.NORM(0.05,AL6,'Choix pédagogiques'!$C17))),"")) | AM7: =IF(OR('Choix pédagogiques'!$C$3=1,'Choix pédagogiques'!$C$3=2),IF(OR(COUNT(AM13:AM1012)<2,'Choix pédagogiques'!$C11=""),"",IF(AM6=0,0,_xlfn.CONFIDENCE.NORM(0.05,AM6,'Choix pédagogiques'!$C11))),IF('Choix pédagogiques'!$C$3=3,IF(OR(COUNT(AM13:AM1012)<2,'Choix pédagogiques'!$C17=""),"",IF(AM6=0,0,_xlfn.CONFIDENCE.NORM(0.05,AM6,'Choix pédagogiques'!$C17))),"")) | AN7: =IF(OR('Choix pédagogiques'!$C$3=1,'Choix pédagogiques'!$C$3=2),IF(OR(COUNT(AN13:AN1012)<2,'Choix pédagogiques'!$C11=""),"",IF(AN6=0,0,_xlfn.CONFIDENCE.NORM(0.05,AN6,'Choix pédagogiques'!$C11))),IF('Choix pédagogiques'!$C$3=3,IF(OR(COUNT(AN13:AN1012)<2,'Choix pédagogiques'!$C17=""),"",IF(AN6=0,0,_xlfn.CONFIDENCE.NORM(0.05,AN6,'Choix pédagogiques'!$C17))),"")) | AQ7: Intervalle de confiance | AR7: =IF(OR('Choix pédagogiques'!$C$3=1,'Choix pédagogiques'!$C$3=2),IF(OR(COUNT(AR13:AR1012)<2,'Choix pédagogiques'!$C10=""),"",IF(AR6=0,0,_xlfn.CONFIDENCE.NORM(0.05,AR6,'Choix pédagogiques'!$C10))),IF('Choix pédagogiques'!$C$3=3,IF(OR(COUNT(AR13:AR1012)<2,'Choix pédagogiques'!$C17=""),"",IF(AR6=0,0,_xlfn.CONFIDENCE.NORM(0.05,AR6,'Choix pédagogiques'!$C17))),"")) | AS7: =IF(OR('Choix pédagogiques'!$C$3=1,'Choix pédagogiques'!$C$3=2),IF(OR(COUNT(AS13:AS1012)<2,'Choix pédagogiques'!$C10=""),"",IF(AS6=0,0,_xlfn.CONFIDENCE.NORM(0.05,AS6,'Choix pédagogiques'!$C10))),IF('Choix pédagogiques'!$C$3=3,IF(OR(COUNT(AS13:AS1012)<2,'Choix pédagogiques'!$C17=""),"",IF(AS6=0,0,_xlfn.CONFIDENCE.NORM(0.05,AS6,'Choix pédagogiques'!$C17))),"")) | AT7: =IF(OR('Choix pédagogiques'!$C$3=1,'Choix pédagogiques'!$C$3=2),IF(OR(COUNT(AT13:AT1012)<2,'Choix pédagogiques'!$C10=""),"",IF(AT6=0,0,_xlfn.CONFIDENCE.NORM(0.05,AT6,'Choix pédagogiques'!$C10))),IF('Choix pédagogiques'!$C$3=3,IF(OR(COUNT(AT13:AT1012)<2,'Choix pédagogiques'!$C17=""),"",IF(AT6=0,0,_xlfn.CONFIDENCE.NORM(0.05,AT6,'Choix pédagogiques'!$C17))),"")) | AV7: Intervalle de confiance | AW7: =IF(OR('Choix pédagogiques'!$C$3=1,'Choix pédagogiques'!$C$3=2),IF(OR(COUNT(AW13:AW1012)<2,'Choix pédagogiques'!$C11=""),"",IF(AW6=0,0,_xlfn.CONFIDENCE.NORM(0.05,AW6,'Choix pédagogiques'!$C11))),IF('Choix pédagogiques'!$C$3=3,IF(OR(COUNT(AW13:AW1012)<2,'Choix pédagogiques'!$C17=""),"",IF(AW6=0,0,_xlfn.CONFIDENCE.NORM(0.05,AW6,'Choix pédagogiques'!$C17))),"")) | AX7: =IF(OR('Choix pédagogiques'!$C$3=1,'Choix pédagogiques'!$C$3=2),IF(OR(COUNT(AX13:AX1012)<2,'Choix pédagogiques'!$C11=""),"",IF(AX6=0,0,_xlfn.CONFIDENCE.NORM(0.05,AX6,'Choix pédagogiques'!$C11))),IF('Choix pédagogiques'!$C$3=3,IF(OR(COUNT(AX13:AX1012)<2,'Choix pédagogiques'!$C17=""),"",IF(AX6=0,0,_xlfn.CONFIDENCE.NORM(0.05,AX6,'Choix pédagogiques'!$C17))),"")) | AY7: =IF(OR('Choix pédagogiques'!$C$3=1,'Choix pédagogiques'!$C$3=2),IF(OR(COUNT(AY13:AY1012)<2,'Choix pédagogiques'!$C11=""),"",IF(AY6=0,0,_xlfn.CONFIDENCE.NORM(0.05,AY6,'Choix pédagogiques'!$C11))),IF('Choix pédagogiques'!$C$3=3,IF(OR(COUNT(AY13:AY1012)<2,'Choix pédagogiques'!$C17=""),"",IF(AY6=0,0,_xlfn.CONFIDENCE.NORM(0.05,AY6,'Choix pédagogiques'!$C17))),"")) | BA7: Intervalle de confiance | BB7: =IF(OR('Choix pédagogiques'!$C$3=1,'Choix pédagogiques'!$C$3=2),IF(OR(COUNT(BB13:BB1012)<2,'Choix pédagogiques'!$C10=""),"",IF(BB6=0,0,_xlfn.CONFIDENCE.NORM(0.05,BB6,'Choix pédagogiques'!$C10))),IF('Choix pédagogiques'!$C$3=3,IF(OR(COUNT(BB13:BB1012)<2,'Choix pédagogiques'!$C17=""),"",IF(BB6=0,0,_xlfn.CONFIDENCE.NORM(0.05,BB6,'Choix pédagogiques'!$C17))),"")) | BC7: =IF(OR('Choix pédagogiques'!$C$3=1,'Choix pédagogiques'!$C$3=2),IF(OR(COUNT(BC13:BC1012)<2,'Choix pédagogiques'!$C10=""),"",IF(BC6=0,0,_xlfn.CONFIDENCE.NORM(0.05,BC6,'Choix pédagogiques'!$C10))),IF('Choix pédagogiques'!$C$3=3,IF(OR(COUNT(BC13:BC1012)<2,'Choix pédagogiques'!$C17=""),"",IF(BC6=0,0,_xlfn.CONFIDENCE.NORM(0.05,BC6,'Choix pédagogiques'!$C17))),"")) | BD7: =IF(OR('Choix pédagogiques'!$C$3=1,'Choix pédagogiques'!$C$3=2),IF(OR(COUNT(BD13:BD1012)<2,'Choix pédagogiques'!$C10=""),"",IF(BD6=0,0,_xlfn.CONFIDENCE.NORM(0.05,BD6,'Choix pédagogiques'!$C10))),IF('Choix pédagogiques'!$C$3=3,IF(OR(COUNT(BD13:BD1012)<2,'Choix pédagogiques'!$C17=""),"",IF(BD6=0,0,_xlfn.CONFIDENCE.NORM(0.05,BD6,'Choix pédagogiques'!$C17))),"")) | BF7: Intervalle de confiance | BG7: =IF(OR('Choix pédagogiques'!$C$3=1,'Choix pédagogiques'!$C$3=2),IF(OR(COUNT(BG13:BG1012)<2,'Choix pédagogiques'!$C11=""),"",IF(BG6=0,0,_xlfn.CONFIDENCE.NORM(0.05,BG6,'Choix pédagogiques'!$C11))),IF('Choix pédagogiques'!$C$3=3,IF(OR(COUNT(BG13:BG1012)<2,'Choix pédagogiques'!$C17=""),"",IF(BG6=0,0,_xlfn.CONFIDENCE.NORM(0.05,BG6,'Choix pédagogiques'!$C17))),"")) | BH7: =IF(OR('Choix pédagogiques'!$C$3=1,'Choix pédagogiques'!$C$3=2),IF(OR(COUNT(BH13:BH1012)<2,'Choix pédagogiques'!$C11=""),"",IF(BH6=0,0,_xlfn.CONFIDENCE.NORM(0.05,BH6,'Choix pédagogiques'!$C11))),IF('Choix pédagogiques'!$C$3=3,IF(OR(COUNT(BH13:BH1012)<2,'Choix pédagogiques'!$C17=""),"",IF(BH6=0,0,_xlfn.CONFIDENCE.NORM(0.05,BH6,'Choix pédagogiques'!$C17))),"")) | BI7: =IF(OR('Choix pédagogiques'!$C$3=1,'Choix pédagogiques'!$C$3=2),IF(OR(COUNT(BI13:BI1012)<2,'Choix pédagogiques'!$C11=""),"",IF(BI6=0,0,_xlfn.CONFIDENCE.NORM(0.05,BI6,'Choix pédagogiques'!$C11))),IF('Choix pédagogiques'!$C$3=3,IF(OR(COUNT(BI13:BI1012)<2,'Choix pédagogiques'!$C17=""),"",IF(BI6=0,0,_xlfn.CONFIDENCE.NORM(0.05,BI6,'Choix pédagogiques'!$C17))),"")) | BL7: Pourcentage de présents | BM7: =IF(OR('Choix pédagogiques'!$C$3=3,BM6="?",BM6=""),"",BM5/BM6) | BN7: =IF(OR('Choix pédagogiques'!$C$3=3,BN6="?",BN6=""),"",BN5/BN6) | BO7: =IF(OR('Choix pédagogiques'!$C$3=1,'Choix pédagogiques'!$C$3=2,BO6="?",BO6=""),"",BO5/BO6)
A8: Minimum | B8: =IF(COUNT(B13:B1012)=0,"",MIN(B13:B1012)) | C8: =IF(COUNT(C13:C1012)=0,"",MIN(C13:C1012)) | D8: =IF(COUNT(D13:D1012)=0,"",MIN(D13:D1012)) | F8: Minimum | G8: =IF(COUNT(G13:G1012)=0,"",MIN(G13:G1012)) | H8: =IF(COUNT(H13:H1012)=0,"",MIN(H13:H1012)) | I8: =IF(COUNT(I13:I1012)=0,"",MIN(I13:I1012)) | K8: Minimum | L8: =IF(COUNT(L13:L1012)=0,"",MIN(L13:L1012)) | M8: =IF(COUNT(M13:M1012)=0,"",MIN(M13:M1012)) | N8: =IF(COUNT(N13:N1012)=0,"",MIN(N13:N1012)) | P8: Minimum | Q8: =IF(COUNT(Q13:Q1012)=0,"",MIN(Q13:Q1012)) | R8: =IF(COUNT(R13:R1012)=0,"",MIN(R13:R1012)) | S8: =IF(COUNT(S13:S1012)=0,"",MIN(S13:S1012)) | V8: Minimum | W8: =IF(COUNT(W13:W1012)=0,"",MIN(W13:W1012)) | X8: =IF(COUNT(X13:X1012)=0,"",MIN(X13:X1012)) | Y8: =IF(COUNT(Y13:Y1012)=0,"",MIN(Y13:Y1012)) | AA8: Minimum | AB8: =IF(COUNT(AB13:AB1012)=0,"",MIN(AB13:AB1012)) | AC8: =IF(COUNT(AC13:AC1012)=0,"",MIN(AC13:AC1012)) | AD8: =IF(COUNT(AD13:AD1012)=0,"",MIN(AD13:AD1012)) | AF8: Minimum | AG8: =IF(COUNT(AG13:AG1012)=0,"",MIN(AG13:AG1012)) | AH8: =IF(COUNT(AH13:AH1012)=0,"",MIN(AH13:AH1012)) | AI8: =IF(COUNT(AI13:AI1012)=0,"",MIN(AI13:AI1012)) | AK8: Minimum | AL8: =IF(COUNT(AL13:AL1012)=0,"",MIN(AL13:AL1012)) | AM8: =IF(COUNT(AM13:AM1012)=0,"",MIN(AM13:AM1012)) | AN8: =IF(COUNT(AN13:AN1012)=0,"",MIN(AN13:AN1012)) | AQ8: Minimum | AR8: =IF(COUNT(AR13:AR1012)=0,"",MIN(AR13:AR1012)) | AS8: =IF(COUNT(AS13:AS1012)=0,"",MIN(AS13:AS1012)) | AT8: =IF(COUNT(AT13:AT1012)=0,"",MIN(AT13:AT1012)) | AV8: Minimum | AW8: =IF(COUNT(AW13:AW1012)=0,"",MIN(AW13:AW1012)) | AX8: =IF(COUNT(AX13:AX1012)=0,"",MIN(AX13:AX1012)) | AY8: =IF(COUNT(AY13:AY1012)=0,"",MIN(AY13:AY1012)) | BA8: Minimum | BB8: =IF(COUNT(BB13:BB1012)=0,"",MIN(BB13:BB1012)) | BC8: =IF(COUNT(BC13:BC1012)=0,"",MIN(BC13:BC1012)) | BD8: =IF(COUNT(BD13:BD1012)=0,"",MIN(BD13:BD1012)) | BF8: Minimum | BG8: =IF(COUNT(BG13:BG1012)=0,"",MIN(BG13:BG1012)) | BH8: =IF(COUNT(BH13:BH1012)=0,"",MIN(BH13:BH1012)) | BI8: =IF(COUNT(BI13:BI1012)=0,"",MIN(BI13:BI1012))
A9: Premier quartile | B9: =IF(COUNT(B13:B1012)=0,"",_xlfn.QUARTILE.INC(B13:B1012,1)) | C9: =IF(COUNT(C13:C1012)=0,"",_xlfn.QUARTILE.INC(C13:C1012,1)) | D9: =IF(COUNT(D13:D1012)=0,"",_xlfn.QUARTILE.INC(D13:D1012,1)) | F9: Premier quartile | G9: =IF(COUNT(G13:G1012)=0,"",_xlfn.QUARTILE.INC(G13:G1012,1)) | H9: =IF(COUNT(H13:H1012)=0,"",_xlfn.QUARTILE.INC(H13:H1012,1)) | I9: =IF(COUNT(I13:I1012)=0,"",_xlfn.QUARTILE.INC(I13:I1012,1)) | K9: Premier quartile | L9: =IF(COUNT(L13:L1012)=0,"",_xlfn.QUARTILE.INC(L13:L1012,1)) | M9: =IF(COUNT(M13:M1012)=0,"",_xlfn.QUARTILE.INC(M13:M1012,1)) | N9: =IF(COUNT(N13:N1012)=0,"",_xlfn.QUARTILE.INC(N13:N1012,1)) | P9: Premier quartile | Q9: =IF(COUNT(Q13:Q1012)=0,"",_xlfn.QUARTILE.INC(Q13:Q1012,1)) | R9: =IF(COUNT(R13:R1012)=0,"",_xlfn.QUARTILE.INC(R13:R1012,1)) | S9: =IF(COUNT(S13:S1012)=0,"",_xlfn.QUARTILE.INC(S13:S1012,1)) | V9: Premier quartile | W9: =IF(COUNT(W13:W1012)=0,"",_xlfn.QUARTILE.INC(W13:W1012,1)) | X9: =IF(COUNT(X13:X1012)=0,"",_xlfn.QUARTILE.INC(X13:X1012,1)) | Y9: =IF(COUNT(Y13:Y1012)=0,"",_xlfn.QUARTILE.INC(Y13:Y1012,1)) | AA9: Premier quartile | AB9: =IF(COUNT(AB13:AB1012)=0,"",_xlfn.QUARTILE.INC(AB13:AB1012,1)) | AC9: =IF(COUNT(AC13:AC1012)=0,"",_xlfn.QUARTILE.INC(AC13:AC1012,1)) | AD9: =IF(COUNT(AD13:AD1012)=0,"",_xlfn.QUARTILE.INC(AD13:AD1012,1)) | AF9: Premier quartile | AG9: =IF(COUNT(AG13:AG1012)=0,"",_xlfn.QUARTILE.INC(AG13:AG1012,1)) | AH9: =IF(COUNT(AH13:AH1012)=0,"",_xlfn.QUARTILE.INC(AH13:AH1012,1)) | AI9: =IF(COUNT(AI13:AI1012)=0,"",_xlfn.QUARTILE.INC(AI13:AI1012,1)) | AK9: Premier quartile | AL9: =IF(COUNT(AL13:AL1012)=0,"",_xlfn.QUARTILE.INC(AL13:AL1012,1)) | AM9: =IF(COUNT(AM13:AM1012)=0,"",_xlfn.QUARTILE.INC(AM13:AM1012,1)) | AN9: =IF(COUNT(AN13:AN1012)=0,"",_xlfn.QUARTILE.INC(AN13:AN1012,1)) | AQ9: Premier quartile | AR9: =IF(COUNT(AR13:AR1012)=0,"",_xlfn.QUARTILE.INC(AR13:AR1012,1)) | AS9: =IF(COUNT(AS13:AS1012)=0,"",_xlfn.QUARTILE.INC(AS13:AS1012,1)) | AT9: =IF(COUNT(AT13:AT1012)=0,"",_xlfn.QUARTILE.INC(AT13:AT1012,1)) | AV9: Premier quartile | AW9: =IF(COUNT(AW13:AW1012)=0,"",_xlfn.QUARTILE.INC(AW13:AW1012,1)) | AX9: =IF(COUNT(AX13:AX1012)=0,"",_xlfn.QUARTILE.INC(AX13:AX1012,1)) | AY9: =IF(COUNT(AY13:AY1012)=0,"",_xlfn.QUARTILE.INC(AY13:AY1012,1)) | BA9: Premier quartile | BB9: =IF(COUNT(BB13:BB1012)=0,"",_xlfn.QUARTILE.INC(BB13:BB1012,1)) | BC9: =IF(COUNT(BC13:BC1012)=0,"",_xlfn.QUARTILE.INC(BC13:BC1012,1)) | BD9: =IF(COUNT(BD13:BD1012)=0,"",_xlfn.QUARTILE.INC(BD13:BD1012,1)) | BF9: Premier quartile | BG9: =IF(COUNT(BG13:BG1012)=0,"",_xlfn.QUARTILE.INC(BG13:BG1012,1)) | BH9: =IF(COUNT(BH13:BH1012)=0,"",_xlfn.QUARTILE.INC(BH13:BH1012,1)) | BI9: =IF(COUNT(BI13:BI1012)=0,"",_xlfn.QUARTILE.INC(BI13:BI1012,1))
A10: Médiane | B10: =IF(COUNT(B13:B1012)=0,"",MEDIAN(B13:B1012)) | C10: =IF(COUNT(C13:C1012)=0,"",MEDIAN(C13:C1012)) | D10: =IF(COUNT(D13:D1012)=0,"",MEDIAN(D13:D1012)) | F10: Médiane | G10: =IF(COUNT(G13:G1012)=0,"",MEDIAN(G13:G1012)) | H10: =IF(COUNT(H13:H1012)=0,"",MEDIAN(H13:H1012)) | I10: =IF(COUNT(I13:I1012)=0,"",MEDIAN(I13:I1012)) | K10: Médiane | L10: =IF(COUNT(L13:L1012)=0,"",MEDIAN(L13:L1012)) | M10: =IF(COUNT(M13:M1012)=0,"",MEDIAN(M13:M1012)) | N10: =IF(COUNT(N13:N1012)=0,"",MEDIAN(N13:N1012)) | P10: Médiane | Q10: =IF(COUNT(Q13:Q1012)=0,"",MEDIAN(Q13:Q1012)) | R10: =IF(COUNT(R13:R1012)=0,"",MEDIAN(R13:R1012)) | S10: =IF(COUNT(S13:S1012)=0,"",MEDIAN(S13:S1012)) | V10: Médiane | W10: =IF(COUNT(W13:W1012)=0,"",MEDIAN(W13:W1012)) | X10: =IF(COUNT(X13:X1012)=0,"",MEDIAN(X13:X1012)) | Y10: =IF(COUNT(Y13:Y1012)=0,"",MEDIAN(Y13:Y1012)) | AA10: Médiane | AB10: =IF(COUNT(AB13:AB1012)=0,"",MEDIAN(AB13:AB1012)) | AC10: =IF(COUNT(AC13:AC1012)=0,"",MEDIAN(AC13:AC1012)) | AD10: =IF(COUNT(AD13:AD1012)=0,"",MEDIAN(AD13:AD1012)) | AF10: Médiane | AG10: =IF(COUNT(AG13:AG1012)=0,"",MEDIAN(AG13:AG1012)) | AH10: =IF(COUNT(AH13:AH1012)=0,"",MEDIAN(AH13:AH1012)) | AI10: =IF(COUNT(AI13:AI1012)=0,"",MEDIAN(AI13:AI1012)) | AK10: Médiane | AL10: =IF(COUNT(AL13:AL1012)=0,"",MEDIAN(AL13:AL1012)) | AM10: =IF(COUNT(AM13:AM1012)=0,"",MEDIAN(AM13:AM1012)) | AN10: =IF(COUNT(AN13:AN1012)=0,"",MEDIAN(AN13:AN1012)) | AQ10: Médiane | AR10: =IF(COUNT(AR13:AR1012)=0,"",MEDIAN(AR13:AR1012)) | AS10: =IF(COUNT(AS13:AS1012)=0,"",MEDIAN(AS13:AS1012)) | AT10: =IF(COUNT(AT13:AT1012)=0,"",MEDIAN(AT13:AT1012)) | AV10: Médiane | AW10: =IF(COUNT(AW13:AW1012)=0,"",MEDIAN(AW13:AW1012)) | AX10: =IF(COUNT(AX13:AX1012)=0,"",MEDIAN(AX13:AX1012)) | AY10: =IF(COUNT(AY13:AY1012)=0,"",MEDIAN(AY13:AY1012)) | BA10: Médiane | BB10: =IF(COUNT(BB13:BB1012)=0,"",MEDIAN(BB13:BB1012)) | BC10: =IF(COUNT(BC13:BC1012)=0,"",MEDIAN(BC13:BC1012)) | BD10: =IF(COUNT(BD13:BD1012)=0,"",MEDIAN(BD13:BD1012)) | BF10: Médiane | BG10: =IF(COUNT(BG13:BG1012)=0,"",MEDIAN(BG13:BG1012)) | BH10: =IF(COUNT(BH13:BH1012)=0,"",MEDIAN(BH13:BH1012)) | BI10: =IF(COUNT(BI13:BI1012)=0,"",MEDIAN(BI13:BI1012))
A11: Troisième quartile | B11: =IF(COUNT(B13:B1012)=0,"",_xlfn.QUARTILE.INC(B13:B1012,3)) | C11: =IF(COUNT(C13:C1012)=0,"",_xlfn.QUARTILE.INC(C13:C1012,3)) | D11: =IF(COUNT(D13:D1012)=0,"",_xlfn.QUARTILE.INC(D13:D1012,3)) | F11: Troisième quartile | G11: =IF(COUNT(G13:G1012)=0,"",_xlfn.QUARTILE.INC(G13:G1012,3)) | H11: =IF(COUNT(H13:H1012)=0,"",_xlfn.QUARTILE.INC(H13:H1012,3)) | I11: =IF(COUNT(I13:I1012)=0,"",_xlfn.QUARTILE.INC(I13:I1012,3)) | K11: Troisième quartile | L11: =IF(COUNT(L13:L1012)=0,"",_xlfn.QUARTILE.INC(L13:L1012,3)) | M11: =IF(COUNT(M13:M1012)=0,"",_xlfn.QUARTILE.INC(M13:M1012,3)) | N11: =IF(COUNT(N13:N1012)=0,"",_xlfn.QUARTILE.INC(N13:N1012,3)) | P11: Troisième quartile | Q11: =IF(COUNT(Q13:Q1012)=0,"",_xlfn.QUARTILE.INC(Q13:Q1012,3)) | R11: =IF(COUNT(R13:R1012)=0,"",_xlfn.QUARTILE.INC(R13:R1012,3)) | S11: =IF(COUNT(S13:S1012)=0,"",_xlfn.QUARTILE.INC(S13:S1012,3)) | V11: Troisième quartile | W11: =IF(COUNT(W13:W1012)=0,"",_xlfn.QUARTILE.INC(W13:W1012,3)) | X11: =IF(COUNT(X13:X1012)=0,"",_xlfn.QUARTILE.INC(X13:X1012,3)) | Y11: =IF(COUNT(Y13:Y1012)=0,"",_xlfn.QUARTILE.INC(Y13:Y1012,3)) | AA11: Troisième quartile | AB11: =IF(COUNT(AB13:AB1012)=0,"",_xlfn.QUARTILE.INC(AB13:AB1012,3)) | AC11: =IF(COUNT(AC13:AC1012)=0,"",_xlfn.QUARTILE.INC(AC13:AC1012,3)) | AD11: =IF(COUNT(AD13:AD1012)=0,"",_xlfn.QUARTILE.INC(AD13:AD1012,3)) | AF11: Troisième quartile | AG11: =IF(COUNT(AG13:AG1012)=0,"",_xlfn.QUARTILE.INC(AG13:AG1012,3)) | AH11: =IF(COUNT(AH13:AH1012)=0,"",_xlfn.QUARTILE.INC(AH13:AH1012,3)) | AI11: =IF(COUNT(AI13:AI1012)=0,"",_xlfn.QUARTILE.INC(AI13:AI1012,3)) | AK11: Troisième quartile | AL11: =IF(COUNT(AL13:AL1012)=0,"",_xlfn.QUARTILE.INC(AL13:AL1012,3)) | AM11: =IF(COUNT(AM13:AM1012)=0,"",_xlfn.QUARTILE.INC(AM13:AM1012,3)) | AN11: =IF(COUNT(AN13:AN1012)=0,"",_xlfn.QUARTILE.INC(AN13:AN1012,3)) | AQ11: Troisième quartile | AR11: =IF(COUNT(AR13:AR1012)=0,"",_xlfn.QUARTILE.INC(AR13:AR1012,3)) | AS11: =IF(COUNT(AS13:AS1012)=0,"",_xlfn.QUARTILE.INC(AS13:AS1012,3)) | AT11: =IF(COUNT(AT13:AT1012)=0,"",_xlfn.QUARTILE.INC(AT13:AT1012,3)) | AV11: Troisième quartile | AW11: =IF(COUNT(AW13:AW1012)=0,"",_xlfn.QUARTILE.INC(AW13:AW1012,3)) | AX11: =IF(COUNT(AX13:AX1012)=0,"",_xlfn.QUARTILE.INC(AX13:AX1012,3)) | AY11: =IF(COUNT(AY13:AY1012)=0,"",_xlfn.QUARTILE.INC(AY13:AY1012,3)) | BA11: Troisième quartile | BB11: =IF(COUNT(BB13:BB1012)=0,"",_xlfn.QUARTILE.INC(BB13:BB1012,3)) | BC11: =IF(COUNT(BC13:BC1012)=0,"",_xlfn.QUARTILE.INC(BC13:BC1012,3)) | BD11: =IF(COUNT(BD13:BD1012)=0,"",_xlfn.QUARTILE.INC(BD13:BD1012,3)) | BF11: Troisième quartile | BG11: =IF(COUNT(BG13:BG1012)=0,"",_xlfn.QUARTILE.INC(BG13:BG1012,3)) | BH11: =IF(COUNT(BH13:BH1012)=0,"",_xlfn.QUARTILE.INC(BH13:BH1012,3)) | BI11: =IF(COUNT(BI13:BI1012)=0,"",_xlfn.QUARTILE.INC(BI13:BI1012,3))
A12: Maximum | B12: =IF(COUNT(B13:B1012)=0,"",MAX(B13:B1012)) | C12: =IF(COUNT(C13:C1012)=0,"",MAX(C13:C1012)) | D12: =IF(COUNT(D13:D1012)=0,"",MAX(D13:D1012)) | F12: Maximum | G12: =IF(COUNT(G13:G1012)=0,"",MAX(G13:G1012)) | H12: =IF(COUNT(H13:H1012)=0,"",MAX(H13:H1012)) | I12: =IF(COUNT(I13:I1012)=0,"",MAX(I13:I1012)) | K12: Maximum | L12: =IF(COUNT(L13:L1012)=0,"",MAX(L13:L1012)) | M12: =IF(COUNT(M13:M1012)=0,"",MAX(M13:M1012)) | N12: =IF(COUNT(N13:N1012)=0,"",MAX(N13:N1012)) | P12: Maximum | Q12: =IF(COUNT(Q13:Q1012)=0,"",MAX(Q13:Q1012)) | R12: =IF(COUNT(R13:R1012)=0,"",MAX(R13:R1012)) | S12: =IF(COUNT(S13:S1012)=0,"",MAX(S13:S1012)) | V12: Maximum | W12: =IF(COUNT(W13:W1012)=0,"",MAX(W13:W1012)) | X12: =IF(COUNT(X13:X1012)=0,"",MAX(X13:X1012)) | Y12: =IF(COUNT(Y13:Y1012)=0,"",MAX(Y13:Y1012)) | AA12: Maximum | AB12: =IF(COUNT(AB13:AB1012)=0,"",MAX(AB13:AB1012)) | AC12: =IF(COUNT(AC13:AC1012)=0,"",MAX(AC13:AC1012)) | AD12: =IF(COUNT(AD13:AD1012)=0,"",MAX(AD13:AD1012)) | AF12: Maximum | AG12: =IF(COUNT(AG13:AG1012)=0,"",MAX(AG13:AG1012)) | AH12: =IF(COUNT(AH13:AH1012)=0,"",MAX(AH13:AH1012)) | AI12: =IF(COUNT(AI13:AI1012)=0,"",MAX(AI13:AI1012)) | AK12: Maximum | AL12: =IF(COUNT(AL13:AL1012)=0,"",MAX(AL13:AL1012)) | AM12: =IF(COUNT(AM13:AM1012)=0,"",MAX(AM13:AM1012)) | AN12: =IF(COUNT(AN13:AN1012)=0,"",MAX(AN13:AN1012)) | AQ12: Maximum | AR12: =IF(COUNT(AR13:AR1012)=0,"",MAX(AR13:AR1012)) | AS12: =IF(COUNT(AS13:AS1012)=0,"",MAX(AS13:AS1012)) | AT12: =IF(COUNT(AT13:AT1012)=0,"",MAX(AT13:AT1012)) | AV12: Maximum | AW12: =IF(COUNT(AW13:AW1012)=0,"",MAX(AW13:AW1012)) | AX12: =IF(COUNT(AX13:AX1012)=0,"",MAX(AX13:AX1012)) | AY12: =IF(COUNT(AY13:AY1012)=0,"",MAX(AY13:AY1012)) | BA12: Maximum | BB12: =IF(COUNT(BB13:BB1012)=0,"",MAX(BB13:BB1012)) | BC12: =IF(COUNT(BC13:BC1012)=0,"",MAX(BC13:BC1012)) | BD12: =IF(COUNT(BD13:BD1012)=0,"",MAX(BD13:BD1012)) | BF12: Maximum | BG12: =IF(COUNT(BG13:BG1012)=0,"",MAX(BG13:BG1012)) | BH12: =IF(COUNT(BH13:BH1012)=0,"",MAX(BH13:BH1012)) | BI12: =IF(COUNT(BI13:BI1012)=0,"",MAX(BI13:BI1012))
A13: Apprenant 1 | F13: Apprenant 1 ou 1' | K13: =IF($A13<>"",$A13,"") -> Apprenant 1 | L13: =IF(AND($B13<>"",$C13<>""),$C13-$B13,"") | M13: =IF(AND($B13<>"",$D13<>""),$D13-$B13,"") | N13: =IF(AND($C13<>"",$D13<>""),$D13-$C13,"") | O13: =IF($E13<>"",$E13,"") | P13: =IF($F13<>"",$F13,"") -> Apprenant 1 ou 1' | Q13: =IF(AND($G13<>"",$H13<>""),$H13-$G13,"") | R13: =IF(AND($G13<>"",$I13<>""),$I13-$G13,"") | S13: =IF(AND($H13<>"",$I13<>""),$I13-$H13,"") | T13: =IF($J13<>"",$J13,"") | V13: =IF($A13<>"",$A13,"") -> Apprenant 1 | W13: =IF(AND(OR('Choix pédagogiques'!$C$3=1,'Choix pédagogiques'!$C$3=2),$BM13=1),B13,IF(AND('Choix pédagogiques'!$C$3=3,$BO13=1),B13,"")) | X13: =IF(AND(OR('Choix pédagogiques'!$C$3=1,'Choix pédagogiques'!$C$3=2),$BM13=1),C13,IF(AND('Choix pédagogiques'!$C$3=3,$BO13=1),C13,"")) | Y13: =IF(AND(OR('Choix pédagogiques'!$C$3=1,'Choix pédagogiques'!$C$3=2),$BM13=1),D13,IF(AND('Choix pédagogiques'!$C$3=3,$BO13=1),D13,"")) | Z13: =IF($E13<>"",$E13,"") | AA13: =IF($F13<>"",$F13,"") -> Apprenant 1 ou 1' | AB13: =IF(AND(OR('Choix pédagogiques'!$C$3=1,'Choix pédagogiques'!$C$3=2),$BN13=1),G13,IF(AND('Choix pédagogiques'!$C$3=3,$BO13=1),G13,"")) | AC13: =IF(AND(OR('Choix pédagogiques'!$C$3=1,'Choix pédagogiques'!$C$3=2),$BN13=1),H13,IF(AND('Choix pédagogiques'!$C$3=3,$BO13=1),H13,"")) | AD13: =IF(AND(OR('Choix pédagogiques'!$C$3=1,'Choix pédagogiques'!$C$3=2),$BN13=1),I13,IF(AND('Choix pédagogiques'!$C$3=3,$BO13=1),I13,"")) | AE13: =IF($J13<>"",$J13,"") | AF13: =IF($A13<>"",$A13,"") -> Apprenant 1 | AG13: =IF(AND($W13<>"",$X13<>""),$X13-$W13,"") | AH13: =IF(AND($W13<>"",$Y13<>""),$Y13-$W13,"") | AI13: =IF(AND($X13<>"",$Y13<>""),$Y13-$X13,"") | AJ13: =IF($E13<>"",$E13,"") | AK13: =IF($F13<>"",$F13,"") -> Apprenant 1 ou 1' | AL13: =IF(AND($AB13<>"",$AC13<>""),$AC13-$AB13,"") | AM13: =IF(AND($AB13<>"",$AD13<>""),$AD13-$AB13,"") | AN13: =IF(AND($AC13<>"",$AD13<>""),$AD13-$AC13,"") | AO13: =IF($J13<>"",$J13,"") | AQ13: =IF($A13<>"",$A13,"") -> Apprenant 1 | AR13: =IF(AND('Choix pédagogiques'!$C$4<>"?",'Choix pédagogiques'!$C$5<>"?",W13<>""),(W13-'Choix pédagogiques'!$C$4)/('Choix pédagogiques'!$C$5-'Choix pédagogiques'!$C$4),"") | AS13: =IF(AND('Choix pédagogiques'!$C$4<>"?",'Choix pédagogiques'!$C$5<>"?",X13<>""),(X13-'Choix pédagogiques'!$C$4)/('Choix pédagogiques'!$C$5-'Choix pédagogiques'!$C$4),"") | AT13: =IF(AND('Choix pédagogiques'!$C$4<>"?",'Choix pédagogiques'!$C$5<>"?",Y13<>""),(Y13-'Choix pédagogiques'!$C$4)/('Choix pédagogiques'!$C$5-'Choix pédagogiques'!$C$4),"") | AU13: =IF($E13<>"",$E13,"") | AV13: =IF($F13<>"",$F13,"") -> Apprenant 1 ou 1' | AW13: =IF(AND('Choix pédagogiques'!$C$4<>"?",'Choix pédagogiques'!$C$5<>"?",AB13<>""),(AB13-'Choix pédagogiques'!$C$4)/('Choix pédagogiques'!$C$5-'Choix pédagogiques'!$C$4),"") | AX13: =IF(AND('Choix pédagogiques'!$C$4<>"?",'Choix pédagogiques'!$C$5<>"?",AC13<>""),(AC13-'Choix pédagogiques'!$C$4)/('Choix pédagogiques'!$C$5-'Choix pédagogiques'!$C$4),"") | AY13: =IF(AND('Choix pédagogiques'!$C$4<>"?",'Choix pédagogiques'!$C$5<>"?",AD13<>""),(AD13-'Choix pédagogiques'!$C$4)/('Choix pédagogiques'!$C$5-'Choix pédagogiques'!$C$4),"") | AZ13: =IF($J13<>"",$J13,"") | BA13: =IF($A13<>"",$A13,"") -> Apprenant 1 | BB13: =IF(AND($AR13<>"",$AS13<>""),$AS13-$AR13,"") | BC13: =IF(AND($AR13<>"",$AT13<>""),$AT13-$AR13,"") | BD13: =IF(AND($AS13<>"",$AT13<>""),$AT13-$AS13,"") | BE13: =IF($E13<>"",$E13,"") | BF13: =IF($F13<>"",$F13,"") -> Apprenant 1 ou 1' | BG13: =IF(AND($AW13<>"",$AX13<>""),$AX13-$AW13,"") | BH13: =IF(AND($AW13<>"",$AY13<>""),$AY13-$AW13,"") | BI13: =IF(AND($AX13<>"",$AY13<>""),$AY13-$AX13,"") | BJ13: =IF($J13<>"",$J13,"") | BM13: =IF(OR(COUNT(B13:D1012)=0,AND('Choix pédagogiques'!$C$3<>1,'Choix pédagogiques'!$C$3<>2)),"",IF(AND(OR('Choix pédagogiques'!$C$3=1,'Choix pédagogiques'!$C$3=2),$B13<>"",$C13<>"",$D13<>""),1,0)) | BN13: =IF(OR(COUNT(G13:I1012)=0,AND('Choix pédagogiques'!$C$3<>1,'Choix pédagogiques'!$C$3<>2)),"",IF(AND(OR('Choix pédagogiques'!$C$3=1,'Choix pédagogiques'!$C$3=2),AND($G13<>"",$H13<>"",$I13<>"")),1,0)) | BO13: =IF(OR(COUNT(B13:D1012)=0,COUNT(G13:I1012)=0,'Choix pédagogiques'!C$3<>3),"",IF(AND('Choix pédagogiques'!$C$3=3,$B13<>"",$C13<>"",$D13<>"",$G13<>"",$H13<>"",$I13<>""),1,0)) | BR13: 977 | BS13: 1953
A14: Apprenant 2 | F14: Apprenant 2 ou 2' | K14: =IF($A14<>"",$A14,"") -> Apprenant 2 | L14: =IF(AND($B14<>"",$C14<>""),$C14-$B14,"") | M14: =IF(AND($B14<>"",$D14<>""),$D14-$B14,"") | N14: =IF(AND($C14<>"",$D14<>""),$D14-$C14,"") | O14: =IF($E14<>"",$E14,"") | P14: =IF($F14<>"",$F14,"") -> Apprenant 2 ou 2' | Q14: =IF(AND($G14<>"",$H14<>""),$H14-$G14,"") | R14: =IF(AND($G14<>"",$I14<>""),$I14-$G14,"") | S14: =IF(AND($H14<>"",$I14<>""),$I14-$H14,"") | T14: =IF($J14<>"",$J14,"") | V14: =IF($A14<>"",$A14,"") -> Apprenant 2 | W14: =IF(AND(OR('Choix pédagogiques'!$C$3=1,'Choix pédagogiques'!$C$3=2),$BM14=1),B14,IF(AND('Choix pédagogiques'!$C$3=3,$BO14=1),B14,"")) | X14: =IF(AND(OR('Choix pédagogiques'!$C$3=1,'Choix pédagogiques'!$C$3=2),$BM14=1),C14,IF(AND('Choix pédagogiques'!$C$3=3,$BO14=1),C14,"")) | Y14: =IF(AND(OR('Choix pédagogiques'!$C$3=1,'Choix pédagogiques'!$C$3=2),$BM14=1),D14,IF(AND('Choix pédagogiques'!$C$3=3,$BO14=1),D14,"")) | Z14: =IF($E14<>"",$E14,"") | AA14: =IF($F14<>"",$F14,"") -> Apprenant 2 ou 2' | AB14: =IF(AND(OR('Choix pédagogiques'!$C$3=1,'Choix pédagogiques'!$C$3=2),$BN14=1),G14,IF(AND('Choix pédagogiques'!$C$3=3,$BO14=1),G14,"")) | AC14: =IF(AND(OR('Choix pédagogiques'!$C$3=1,'Choix pédagogiques'!$C$3=2),$BN14=1),H14,IF(AND('Choix pédagogiques'!$C$3=3,$BO14=1),H14,"")) | AD14: =IF(AND(OR('Choix pédagogiques'!$C$3=1,'Choix pédagogiques'!$C$3=2),$BN14=1),I14,IF(AND('Choix pédagogiques'!$C$3=3,$BO14=1),I14,"")) | AE14: =IF($J14<>"",$J14,"") | AF14: =IF($A14<>"",$A14,"") -> Apprenant 2 | AG14: =IF(AND($W14<>"",$X14<>""),$X14-$W14,"") | AH14: =IF(AND($W14<>"",$Y14<>""),$Y14-$W14,"") | AI14: =IF(AND($X14<>"",$Y14<>""),$Y14-$X14,"") | AJ14: =IF($E14<>"",$E14,"") | AK14: =IF($F14<>"",$F14,"") -> Apprenant 2 ou 2' | AL14: =IF(AND($AB14<>"",$AC14<>""),$AC14-$AB14,"") | AM14: =IF(AND($AB14<>"",$AD14<>""),$AD14-$AB14,"") | AN14: =IF(AND($AC14<>"",$AD14<>""),$AD14-$AC14,"") | AO14: =IF($J14<>"",$J14,"") | AQ14: =IF($A14<>"",$A14,"") -> Apprenant 2 | AR14: =IF(AND('Choix pédagogiques'!$C$4<>"?",'Choix pédagogiques'!$C$5<>"?",W14<>""),(W14-'Choix pédagogiques'!$C$4)/('Choix pédagogiques'!$C$5-'Choix pédagogiques'!$C$4),"") | AS14: =IF(AND('Choix pédagogiques'!$C$4<>"?",'Choix pédagogiques'!$C$5<>"?",X14<>""),(X14-'Choix pédagogiques'!$C$4)/('Choix pédagogiques'!$C$5-'Choix pédagogiques'!$C$4),"") | AT14: =IF(AND('Choix pédagogiques'!$C$4<>"?",'Choix pédagogiques'!$C$5<>"?",Y14<>""),(Y14-'Choix pédagogiques'!$C$4)/('Choix pédagogiques'!$C$5-'Choix pédagogiques'!$C$4),"") | AU14: =IF($E14<>"",$E14,"") | AV14: =IF($F14<>"",$F14,"") -> Apprenant 2 ou 2' | AW14: =IF(AND('Choix pédagogiques'!$C$4<>"?",'Choix pédagogiques'!$C$5<>"?",AB14<>""),(AB14-'Choix pédagogiques'!$C$4)/('Choix pédagogiques'!$C$5-'Choix pédagogiques'!$C$4),"") | AX14: =IF(AND('Choix pédagogiques'!$C$4<>"?",'Choix pédagogiques'!$C$5<>"?",AC14<>""),(AC14-'Choix pédagogiques'!$C$4)/('Choix pédagogiques'!$C$5-'Choix pédagogiques'!$C$4),"") | AY14: =IF(AND('Choix pédagogiques'!$C$4<>"?",'Choix pédagogiques'!$C$5<>"?",AD14<>""),(AD14-'Choix pédagogiques'!$C$4)/('Choix pédagogiques'!$C$5-'Choix pédagogiques'!$C$4),"") | AZ14: =IF($J14<>"",$J14,"") | BA14: =IF($A14<>"",$A14,"") -> Apprenant 2 | BB14: =IF(AND($AR14<>"",$AS14<>""),$AS14-$AR14,"") | BC14: =IF(AND($AR14<>"",$AT14<>""),$AT14-$AR14,"") | BD14: =IF(AND($AS14<>"",$AT14<>""),$AT14-$AS14,"") | BE14: =IF($E14<>"",$E14,"") | BF14: =IF($F14<>"",$F14,"") -> Apprenant 2 ou 2' | BG14: =IF(AND($AW14<>"",$AX14<>""),$AX14-$AW14,"") | BH14: =IF(AND($AW14<>"",$AY14<>""),$AY14-$AW14,"") | BI14: =IF(AND($AX14<>"",$AY14<>""),$AY14-$AX14,"") | BJ14: =IF($J14<>"",$J14,"") | BM14: =IF(OR(COUNT(B14:D1013)=0,AND('Choix pédagogiques'!$C$3<>1,'Choix pédagogiques'!$C$3<>2)),"",IF(AND(OR('Choix pédagogiques'!$C$3=1,'Choix pédagogiques'!$C$3=2),$B14<>"",$C14<>"",$D14<>""),1,0)) | BN14: =IF(OR(COUNT(G14:I1013)=0,AND('Choix pédagogiques'!$C$3<>1,'Choix pédagogiques'!$C$3<>2)),"",IF(AND(OR('Choix pédagogiques'!$C$3=1,'Choix pédagogiques'!$C$3=2),AND($G14<>"",$H14<>"",$I14<>"")),1,0)) | BO14: =IF(OR(COUNT(B14:D1013)=0,COUNT(G14:I1013)=0,'Choix pédagogiques'!C$3<>3),"",IF(AND('Choix pédagogiques'!$C$3=3,$B14<>"",$C14<>"",$D14<>"",$G14<>"",$H14<>"",$I14<>""),1,0)) | BR14: 429 | BS14: 1016
A15: Apprenant 3 | F15: Apprenant 3 ou 3' | K15: =IF($A15<>"",$A15,"") -> Apprenant 3 | L15: =IF(AND($B15<>"",$C15<>""),$C15-$B15,"") | M15: =IF(AND($B15<>"",$D15<>""),$D15-$B15,"") | N15: =IF(AND($C15<>"",$D15<>""),$D15-$C15,"") | O15: =IF($E15<>"",$E15,"") | P15: =IF($F15<>"",$F15,"") -> Apprenant 3 ou 3' | Q15: =IF(AND($G15<>"",$H15<>""),$H15-$G15,"") | R15: =IF(AND($G15<>"",$I15<>""),$I15-$G15,"") | S15: =IF(AND($H15<>"",$I15<>""),$I15-$H15,"") | T15: =IF($J15<>"",$J15,"") | V15: =IF($A15<>"",$A15,"") -> Apprenant 3 | W15: =IF(AND(OR('Choix pédagogiques'!$C$3=1,'Choix pédagogiques'!$C$3=2),$BM15=1),B15,IF(AND('Choix pédagogiques'!$C$3=3,$BO15=1),B15,"")) | X15: =IF(AND(OR('Choix pédagogiques'!$C$3=1,'Choix pédagogiques'!$C$3=2),$BM15=1),C15,IF(AND('Choix pédagogiques'!$C$3=3,$BO15=1),C15,"")) | Y15: =IF(AND(OR('Choix pédagogiques'!$C$3=1,'Choix pédagogiques'!$C$3=2),$BM15=1),D15,IF(AND('Choix pédagogiques'!$C$3=3,$BO15=1),D15,"")) | Z15: =IF($E15<>"",$E15,"") | AA15: =IF($F15<>"",$F15,"") -> Apprenant 3 ou 3' | AB15: =IF(AND(OR('Choix pédagogiques'!$C$3=1,'Choix pédagogiques'!$C$3=2),$BN15=1),G15,IF(AND('Choix pédagogiques'!$C$3=3,$BO15=1),G15,"")) | AC15: =IF(AND(OR('Choix pédagogiques'!$C$3=1,'Choix pédagogiques'!$C$3=2),$BN15=1),H15,IF(AND('Choix pédagogiques'!$C$3=3,$BO15=1),H15,"")) | AD15: =IF(AND(OR('Choix pédagogiques'!$C$3=1,'Choix pédagogiques'!$C$3=2),$BN15=1),I15,IF(AND('Choix pédagogiques'!$C$3=3,$BO15=1),I15,"")) | AE15: =IF($J15<>"",$J15,"") | AF15: =IF($A15<>"",$A15,"") -> Apprenant 3 | AG15: =IF(AND($W15<>"",$X15<>""),$X15-$W15,"") | AH15: =IF(AND($W15<>"",$Y15<>""),$Y15-$W15,"") | AI15: =IF(AND($X15<>"",$Y15<>""),$Y15-$X15,"") | AJ15: =IF($E15<>"",$E15,"") | AK15: =IF($F15<>"",$F15,"") -> Apprenant 3 ou 3' | AL15: =IF(AND($AB15<>"",$AC15<>""),$AC15-$AB15,"") | AM15: =IF(AND($AB15<>"",$AD15<>""),$AD15-$AB15,"") | AN15: =IF(AND($AC15<>"",$AD15<>""),$AD15-$AC15,"") | AO15: =IF($J15<>"",$J15,"") | AQ15: =IF($A15<>"",$A15,"") -> Apprenant 3 | AR15: =IF(AND('Choix pédagogiques'!$C$4<>"?",'Choix pédagogiques'!$C$5<>"?",W15<>""),(W15-'Choix pédagogiques'!$C$4)/('Choix pédagogiques'!$C$5-'Choix pédagogiques'!$C$4),"") | AS15: =IF(AND('Choix pédagogiques'!$C$4<>"?",'Choix pédagogiques'!$C$5<>"?",X15<>""),(X15-'Choix pédagogiques'!$C$4)/('Choix pédagogiques'!$C$5-'Choix pédagogiques'!$C$4),"") | AT15: =IF(AND('Choix pédagogiques'!$C$4<>"?",'Choix pédagogiques'!$C$5<>"?",Y15<>""),(Y15-'Choix pédagogiques'!$C$4)/('Choix pédagogiques'!$C$5-'Choix pédagogiques'!$C$4),"") | AU15: =IF($E15<>"",$E15,"") | AV15: =IF($F15<>"",$F15,"") -> Apprenant 3 ou 3' | AW15: =IF(AND('Choix pédagogiques'!$C$4<>"?",'Choix pédagogiques'!$C$5<>"?",AB15<>""),(AB15-'Choix pédagogiques'!$C$4)/('Choix pédagogiques'!$C$5-'Choix pédagogiques'!$C$4),"") | AX15: =IF(AND('Choix pédagogiques'!$C$4<>"?",'Choix pédagogiques'!$C$5<>"?",AC15<>""),(AC15-'Choix pédagogiques'!$C$4)/('Choix pédagogiques'!$C$5-'Choix pédagogiques'!$C$4),"") | AY15: =IF(AND('Choix pédagogiques'!$C$4<>"?",'Choix pédagogiques'!$C$5<>"?",AD15<>""),(AD15-'Choix pédagogiques'!$C$4)/('Choix pédagogiques'!$C$5-'Choix pédagogiques'!$C$4),"") | AZ15: =IF($J15<>"",$J15,"") | BA15: =IF($A15<>"",$A15,"") -> Apprenant 3 | BB15: =IF(AND($AR15<>"",$AS15<>""),$AS15-$AR15,"") | BC15: =IF(AND($AR15<>"",$AT15<>""),$AT15-$AR15,"") | BD15: =IF(AND($AS15<>"",$AT15<>""),$AT15-$AS15,"") | BE15: =IF($E15<>"",$E15,"") | BF15: =IF($F15<>"",$F15,"") -> Apprenant 3 ou 3' | BG15: =IF(AND($AW15<>"",$AX15<>""),$AX15-$AW15,"") | BH15: =IF(AND($AW15<>"",$AY15<>""),$AY15-$AW15,"") | BI15: =IF(AND($AX15<>"",$AY15<>""),$AY15-$AX15,"") | BJ15: =IF($J15<>"",$J15,"") | BM15: =IF(OR(COUNT(B15:D1014)=0,AND('Choix pédagogiques'!$C$3<>1,'Choix pédagogiques'!$C$3<>2)),"",IF(AND(OR('Choix pédagogiques'!$C$3=1,'Choix pédagogiques'!$C$3=2),$B15<>"",$C15<>"",$D15<>""),1,0)) | BN15: =IF(OR(COUNT(G15:I1014)=0,AND('Choix pédagogiques'!$C$3<>1,'Choix pédagogiques'!$C$3<>2)),"",IF(AND(OR('Choix pédagogiques'!$C$3=1,'Choix pédagogiques'!$C$3=2),AND($G15<>"",$H15<>"",$I15<>"")),1,0)) | BO15: =IF(OR(COUNT(B15:D1014)=0,COUNT(G15:I1014)=0,'Choix pédagogiques'!C$3<>3),"",IF(AND('Choix pédagogiques'!$C$3=3,$B15<>"",$C15<>"",$D15<>"",$G15<>"",$H15<>"",$I15<>""),1,0)) | BR15: 758 | BS15: 1159
A16: Apprenant 4 | F16: Apprenant 4 ou 4' | K16: =IF($A16<>"",$A16,"") -> Apprenant 4 | L16: =IF(AND($B16<>"",$C16<>""),$C16-$B16,"") | M16: =IF(AND($B16<>"",$D16<>""),$D16-$B16,"") | N16: =IF(AND($C16<>"",$D16<>""),$D16-$C16,"") | O16: =IF($E16<>"",$E16,"") | P16: =IF($F16<>"",$F16,"") -> Apprenant 4 ou 4' | Q16: =IF(AND($G16<>"",$H16<>""),$H16-$G16,"") | R16: =IF(AND($G16<>"",$I16<>""),$I16-$G16,"") | S16: =IF(AND($H16<>"",$I16<>""),$I16-$H16,"") | T16: =IF($J16<>"",$J16,"") | V16: =IF($A16<>"",$A16,"") -> Apprenant 4 | W16: =IF(AND(OR('Choix pédagogiques'!$C$3=1,'Choix pédagogiques'!$C$3=2),$BM16=1),B16,IF(AND('Choix pédagogiques'!$C$3=3,$BO16=1),B16,"")) | X16: =IF(AND(OR('Choix pédagogiques'!$C$3=1,'Choix pédagogiques'!$C$3=2),$BM16=1),C16,IF(AND('Choix pédagogiques'!$C$3=3,$BO16=1),C16,"")) | Y16: =IF(AND(OR('Choix pédagogiques'!$C$3=1,'Choix pédagogiques'!$C$3=2),$BM16=1),D16,IF(AND('Choix pédagogiques'!$C$3=3,$BO16=1),D16,"")) | Z16: =IF($E16<>"",$E16,"") | AA16: =IF($F16<>"",$F16,"") -> Apprenant 4 ou 4' | AB16: =IF(AND(OR('Choix pédagogiques'!$C$3=1,'Choix pédagogiques'!$C$3=2),$BN16=1),G16,IF(AND('Choix pédagogiques'!$C$3=3,$BO16=1),G16,"")) | AC16: =IF(AND(OR('Choix pédagogiques'!$C$3=1,'Choix pédagogiques'!$C$3=2),$BN16=1),H16,IF(AND('Choix pédagogiques'!$C$3=3,$BO16=1),H16,"")) | AD16: =IF(AND(OR('Choix pédagogiques'!$C$3=1,'Choix pédagogiques'!$C$3=2),$BN16=1),I16,IF(AND('Choix pédagogiques'!$C$3=3,$BO16=1),I16,"")) | AE16: =IF($J16<>"",$J16,"") | AF16: =IF($A16<>"",$A16,"") -> Apprenant 4 | AG16: =IF(AND($W16<>"",$X16<>""),$X16-$W16,"") | AH16: =IF(AND($W16<>"",$Y16<>""),$Y16-$W16,"") | AI16: =IF(AND($X16<>"",$Y16<>""),$Y16-$X16,"") | AJ16: =IF($E16<>"",$E16,"") | AK16: =IF($F16<>"",$F16,"") -> Apprenant 4 ou 4' | AL16: =IF(AND($AB16<>"",$AC16<>""),$AC16-$AB16,"") | AM16: =IF(AND($AB16<>"",$AD16<>""),$AD16-$AB16,"") | AN16: =IF(AND($AC16<>"",$AD16<>""),$AD16-$AC16,"") | AO16: =IF($J16<>"",$J16,"") | AQ16: =IF($A16<>"",$A16,"") -> Apprenant 4 | AR16: =IF(AND('Choix pédagogiques'!$C$4<>"?",'Choix pédagogiques'!$C$5<>"?",W16<>""),(W16-'Choix pédagogiques'!$C$4)/('Choix pédagogiques'!$C$5-'Choix pédagogiques'!$C$4),"") | AS16: =IF(AND('Choix pédagogiques'!$C$4<>"?",'Choix pédagogiques'!$C$5<>"?",X16<>""),(X16-'Choix pédagogiques'!$C$4)/('Choix pédagogiques'!$C$5-'Choix pédagogiques'!$C$4),"") | AT16: =IF(AND('Choix pédagogiques'!$C$4<>"?",'Choix pédagogiques'!$C$5<>"?",Y16<>""),(Y16-'Choix pédagogiques'!$C$4)/('Choix pédagogiques'!$C$5-'Choix pédagogiques'!$C$4),"") | AU16: =IF($E16<>"",$E16,"") | AV16: =IF($F16<>"",$F16,"") -> Apprenant 4 ou 4' | AW16: =IF(AND('Choix pédagogiques'!$C$4<>"?",'Choix pédagogiques'!$C$5<>"?",AB16<>""),(AB16-'Choix pédagogiques'!$C$4)/('Choix pédagogiques'!$C$5-'Choix pédagogiques'!$C$4),"") | AX16: =IF(AND('Choix pédagogiques'!$C$4<>"?",'Choix pédagogiques'!$C$5<>"?",AC16<>""),(AC16-'Choix pédagogiques'!$C$4)/('Choix pédagogiques'!$C$5-'Choix pédagogiques'!$C$4),"") | AY16: =IF(AND('Choix pédagogiques'!$C$4<>"?",'Choix pédagogiques'!$C$5<>"?",AD16<>""),(AD16-'Choix pédagogiques'!$C$4)/('Choix pédagogiques'!$C$5-'Choix pédagogiques'!$C$4),"") | AZ16: =IF($J16<>"",$J16,"") | BA16: =IF($A16<>"",$A16,"") -> Apprenant 4 | BB16: =IF(AND($AR16<>"",$AS16<>""),$AS16-$AR16,"") | BC16: =IF(AND($AR16<>"",$AT16<>""),$AT16-$AR16,"") | BD16: =IF(AND($AS16<>"",$AT16<>""),$AT16-$AS16,"") | BE16: =IF($E16<>"",$E16,"") | BF16: =IF($F16<>"",$F16,"") -> Apprenant 4 ou 4' | BG16: =IF(AND($AW16<>"",$AX16<>""),$AX16-$AW16,"") | BH16: =IF(AND($AW16<>"",$AY16<>""),$AY16-$AW16,"") | BI16: =IF(AND($AX16<>"",$AY16<>""),$AY16-$AX16,"") | BJ16: =IF($J16<>"",$J16,"") | BM16: =IF(OR(COUNT(B16:D1015)=0,AND('Choix pédagogiques'!$C$3<>1,'Choix pédagogiques'!$C$3<>2)),"",IF(AND(OR('Choix pédagogiques'!$C$3=1,'Choix pédagogiques'!$C$3=2),$B16<>"",$C16<>"",$D16<>""),1,0)) | BN16: =IF(OR(COUNT(G16:I1015)=0,AND('Choix pédagogiques'!$C$3<>1,'Choix pédagogiques'!$C$3<>2)),"",IF(AND(OR('Choix pédagogiques'!$C$3=1,'Choix pédagogiques'!$C$3=2),AND($G16<>"",$H16<>"",$I16<>"")),1,0)) | BO16: =IF(OR(COUNT(B16:D1015)=0,COUNT(G16:I1015)=0,'Choix pédagogiques'!C$3<>3),"",IF(AND('Choix pédagogiques'!$C$3=3,$B16<>"",$C16<>"",$D16<>"",$G16<>"",$H16<>"",$I16<>""),1,0)) | BR16: 747 | BS16: 1669
A17: Apprenant 5 | F17: Apprenant 5 ou 5' | K17: =IF($A17<>"",$A17,"") -> Apprenant 5 | L17: =IF(AND($B17<>"",$C17<>""),$C17-$B17,"") | M17: =IF(AND($B17<>"",$D17<>""),$D17-$B17,"") | N17: =IF(AND($C17<>"",$D17<>""),$D17-$C17,"") | O17: =IF($E17<>"",$E17,"") | P17: =IF($F17<>"",$F17,"") -> Apprenant 5 ou 5' | Q17: =IF(AND($G17<>"",$H17<>""),$H17-$G17,"") | R17: =IF(AND($G17<>"",$I17<>""),$I17-$G17,"") | S17: =IF(AND($H17<>"",$I17<>""),$I17-$H17,"") | T17: =IF($J17<>"",$J17,"") | V17: =IF($A17<>"",$A17,"") -> Apprenant 5 | W17: =IF(AND(OR('Choix pédagogiques'!$C$3=1,'Choix pédagogiques'!$C$3=2),$BM17=1),B17,IF(AND('Choix pédagogiques'!$C$3=3,$BO17=1),B17,"")) | X17: =IF(AND(OR('Choix pédagogiques'!$C$3=1,'Choix pédagogiques'!$C$3=2),$BM17=1),C17,IF(AND('Choix pédagogiques'!$C$3=3,$BO17=1),C17,"")) | Y17: =IF(AND(OR('Choix pédagogiques'!$C$3=1,'Choix pédagogiques'!$C$3=2),$BM17=1),D17,IF(AND('Choix pédagogiques'!$C$3=3,$BO17=1),D17,"")) | Z17: =IF($E17<>"",$E17,"") | AA17: =IF($F17<>"",$F17,"") -> Apprenant 5 ou 5' | AB17: =IF(AND(OR('Choix pédagogiques'!$C$3=1,'Choix pédagogiques'!$C$3=2),$BN17=1),G17,IF(AND('Choix pédagogiques'!$C$3=3,$BO17=1),G17,"")) | AC17: =IF(AND(OR('Choix pédagogiques'!$C$3=1,'Choix pédagogiques'!$C$3=2),$BN17=1),H17,IF(AND('Choix pédagogiques'!$C$3=3,$BO17=1),H17,"")) | AD17: =IF(AND(OR('Choix pédagogiques'!$C$3=1,'Choix pédagogiques'!$C$3=2),$BN17=1),I17,IF(AND('Choix pédagogiques'!$C$3=3,$BO17=1),I17,"")) | AE17: =IF($J17<>"",$J17,"") | AF17: =IF($A17<>"",$A17,"") -> Apprenant 5 | AG17: =IF(AND($W17<>"",$X17<>""),$X17-$W17,"") | AH17: =IF(AND($W17<>"",$Y17<>""),$Y17-$W17,"") | AI17: =IF(AND($X17<>"",$Y17<>""),$Y17-$X17,"") | AJ17: =IF($E17<>"",$E17,"") | AK17: =IF($F17<>"",$F17,"") -> Apprenant 5 ou 5' | AL17: =IF(AND($AB17<>"",$AC17<>""),$AC17-$AB17,"") | AM17: =IF(AND($AB17<>"",$AD17<>""),$AD17-$AB17,"") | AN17: =IF(AND($AC17<>"",$AD17<>""),$AD17-$AC17,"") | AO17: =IF($J17<>"",$J17,"") | AQ17: =IF($A17<>"",$A17,"") -> Apprenant 5 | AR17: =IF(AND('Choix pédagogiques'!$C$4<>"?",'Choix pédagogiques'!$C$5<>"?",W17<>""),(W17-'Choix pédagogiques'!$C$4)/('Choix pédagogiques'!$C$5-'Choix pédagogiques'!$C$4),"") | AS17: =IF(AND('Choix pédagogiques'!$C$4<>"?",'Choix pédagogiques'!$C$5<>"?",X17<>""),(X17-'Choix pédagogiques'!$C$4)/('Choix pédagogiques'!$C$5-'Choix pédagogiques'!$C$4),"") | AT17: =IF(AND('Choix pédagogiques'!$C$4<>"?",'Choix pédagogiques'!$C$5<>"?",Y17<>""),(Y17-'Choix pédagogiques'!$C$4)/('Choix pédagogiques'!$C$5-'Choix pédagogiques'!$C$4),"") | AU17: =IF($E17<>"",$E17,"") | AV17: =IF($F17<>"",$F17,"") -> Apprenant 5 ou 5' | AW17: =IF(AND('Choix pédagogiques'!$C$4<>"?",'Choix pédagogiques'!$C$5<>"?",AB17<>""),(AB17-'Choix pédagogiques'!$C$4)/('Choix pédagogiques'!$C$5-'Choix pédagogiques'!$C$4),"") | AX17: =IF(AND('Choix pédagogiques'!$C$4<>"?",'Choix pédagogiques'!$C$5<>"?",AC17<>""),(AC17-'Choix pédagogiques'!$C$4)/('Choix pédagogiques'!$C$5-'Choix pédagogiques'!$C$4),"") | AY17: =IF(AND('Choix pédagogiques'!$C$4<>"?",'Choix pédagogiques'!$C$5<>"?",AD17<>""),(AD17-'Choix pédagogiques'!$C$4)/('Choix pédagogiques'!$C$5-'Choix pédagogiques'!$C$4),"") | AZ17: =IF($J17<>"",$J17,"") | BA17: =IF($A17<>"",$A17,"") -> Apprenant 5 | BB17: =IF(AND($AR17<>"",$AS17<>""),$AS17-$AR17,"") | BC17: =IF(AND($AR17<>"",$AT17<>""),$AT17-$AR17,"") | BD17: =IF(AND($AS17<>"",$AT17<>""),$AT17-$AS17,"") | BE17: =IF($E17<>"",$E17,"") | BF17: =IF($F17<>"",$F17,"") -> Apprenant 5 ou 5' | BG17: =IF(AND($AW17<>"",$AX17<>""),$AX17-$AW17,"") | BH17: =IF(AND($AW17<>"",$AY17<>""),$AY17-$AW17,"") | BI17: =IF(AND($AX17<>"",$AY17<>""),$AY17-$AX17,"") | BJ17: =IF($J17<>"",$J17,"") | BM17: =IF(OR(COUNT(B17:D1016)=0,AND('Choix pédagogiques'!$C$3<>1,'Choix pédagogiques'!$C$3<>2)),"",IF(AND(OR('Choix pédagogiques'!$C$3=1,'Choix pédagogiques'!$C$3=2),$B17<>"",$C17<>"",$D17<>""),1,0)) | BN17: =IF(OR(COUNT(G17:I1016)=0,AND('Choix pédagogiques'!$C$3<>1,'Choix pédagogiques'!$C$3<>2)),"",IF(AND(OR('Choix pédagogiques'!$C$3=1,'Choix pédagogiques'!$C$3=2),AND($G17<>"",$H17<>"",$I17<>"")),1,0)) | BO17: =IF(OR(COUNT(B17:D1016)=0,COUNT(G17:I1016)=0,'Choix pédagogiques'!C$3<>3),"",IF(AND('Choix pédagogiques'!$C$3=3,$B17<>"",$C17<>"",$D17<>"",$G17<>"",$H17<>"",$I17<>""),1,0)) | BR17: 998 | BS17: 1374
